Workbook
Name SDBase: ScenarioDefinition!$J$8:$J$526
Name SDParam: ScenarioDefinition!$H$8:$H$526
Name DPCHG: _xlfn.LAMBDA(_xlpm.p_new,_xlpm.p_ref,_xlpm.p_new/_xlpm.p_ref-1)
Name DFAC: _xlfn.LAMBDA(_xlpm.peds,_xlpm.dp,_xlpm.eps,_xlpm.dp*IF(LEFT(_xlpm.peds,3)="Yes",(1+_xlpm.dp)^_xlpm.eps,1))
Name DTARGET: _xlfn.LAMBDA(_xlpm.share,_xlpm.cum,_xlpm.pct,MAX(0,MIN(_xlpm.share,_xlpm.pct-_xlpm.cum+_xlpm.share)))
Name DPITPICK: _xlfn.LAMBDA(_xlpm.method,_xlpm.pa,_xlpm.prop,_xlpm.te,IF(_xlpm.method="Personal Allowance",_xlpm.pa,IF(_xlpm.method="Proportional Compensation",_xlpm.prop,_xlpm.te)))
Name DPOST: _xlfn.LAMBDA(_xlpm.cons,_xlpm.loss_pct,_xlpm.cons*(1+_xlpm.loss_pct/PctPerUnit))
Name DGINI: _xlfn.LAMBDA(_xlpm.cons,_xlpm.weights,1-SUMPRODUCT(_xlpm.cons,_xlpm.weights)/SUM(_xlpm.cons))
Name WEOVal: 'Constants and Mappings'!$F$1969:$AG$2005
Name WEOKey: 'Constants and Mappings'!$A$1969:$A$2005
Name WEOYear: 'Constants and Mappings'!$F$1968:$AG$1968
Name WEOCode: WEO!$D$4:$D$9003
Name WEOLast: WEO!$A$4:$A$9003
Name WEOData: WEO!$G$4:$AU$9003
Name WEOYr: WEO!$G$3:$AU$3
Name ElaSelKey: 'Constants and Mappings'!$A$1805:$A$1924
Name ElaSel: 'Constants and Mappings'!$M$1805:$M$1924
Name EFSelKey: 'Constants and Mappings'!$A$1751:$A$1787
Name EFSel: 'Constants and Mappings'!$K$1751:$K$1787
Name NCEfKey: 'Constants and Mappings'!$A$2411:$A$2946
Name NCEfIn: 'Constants and Mappings'!$I$2411:$I$2946
Name NCEfFin: 'Constants and Mappings'!$J$2411:$J$2946
Name CtryReg: 'Constants and Mappings'!$C$43
Name PIntVal: 'Constants and Mappings'!$J$2014:$AH$2069
Name PIntKey: 'Constants and Mappings'!$A$2014:$A$2069
Name PIntYear: 'Constants and Mappings'!$J$2012:$AH$2012
Name PTechVal: 'Constants and Mappings'!$A$2269:$AU$2277
Name PTechKey: 'Constants and Mappings'!$A$2269:$A$2277
Name PTechHdr: 'Constants and Mappings'!$A$2268:$AU$2268
Name PParVal: 'Constants and Mappings'!$D$2359:$D$2403
Name PParKey: 'Constants and Mappings'!$A$2359:$A$2403
Name PsMinTE: 'Constants and Mappings'!$B$2222
Name PsHydNoRet: 'Constants and Mappings'!$B$2223
Name PsScNonVRE: 'Constants and Mappings'!$B$2224
Name PsScNonNuc: 'Constants and Mappings'!$B$2225
Name PsScCat: 'Constants and Mappings'!$B$2226
Name PsScUser: 'Constants and Mappings'!$B$2227
Name PsWaccSrc: 'Constants and Mappings'!$B$2228
Name PsWaccUser: 'Constants and Mappings'!$B$2229
Name PsWaccMin: 'Constants and Mappings'!$B$2230
Name PsReDecline: 'Constants and Mappings'!$B$2231
Name PsLTHours: 'Constants and Mappings'!$B$2232
Name PsIncElAdj: 'Constants and Mappings'!$B$2233
Name PsPass: 'Constants and Mappings'!$B$2234
Name PsSTAlloc: 'Constants and Mappings'!$B$2235
Name PsSTHours: 'Constants and Mappings'!$B$2236
Name PsSTRatio: 'Constants and Mappings'!$B$2237
Name PsLTAlloc: 'Constants and Mappings'!$B$2238
Name PsLTStart: 'Constants and Mappings'!$B$2239
Name PsAddEff: 'Constants and Mappings'!$B$2240
Name PsMaxCoalCF: 'Constants and Mappings'!$B$2241
Name PsKDisp: 'Constants and Mappings'!$B$2242
Name PsKInv: 'Constants and Mappings'!$B$2243
Name PsMinCost: 'Constants and Mappings'!$B$2244
Name PsEarlyMax: 'Constants and Mappings'!$B$2245
Name PsEarlyBL: 'Constants and Mappings'!$B$2246
Name PsCFMinVRE: 'Constants and Mappings'!$B$2247
Name PsCFMinOth: 'Constants and Mappings'!$B$2248
Name PsCFMax: 'Constants and Mappings'!$B$2249
Name PsCtryWacc: 'Constants and Mappings'!$B$2253

Sheet Cover
A2: CPAT-AI-Distribution v1.2.0: Cover page
A3: The distribution module of the Climate Policy Assessment Tool (CPAT): the effect of the scenarios of the mitigation prototype on households, by decile, in one analysis year.
A5: How to use it (one scenario at a time)
A6: 1. | B6: In the mitigation workbook: define the scenario, recalculate (F9), save.
A7: 2. | B7: In the Master workbook (CPAT-AI-Master_UserGuide.xlsm, active_workbooks): Update Distribution from Mitigation. It copies section 19a of the mitigation workbook into FromMitigation here and recalculates.
A8: 3. | B8: Read the results on Distribution (one column group per scenario, deciles across).
A9: 4. | B9: Distribution settings of a scenario (analysis year, revenue recycling, targeting): ScenarioDefinition, then recalculate (F9).
A11: Link to the mitigation workbook
A12: Mitigation workbook (input) | B12: CPAT-AI-Mitigation_latest.xlsx
B13: The Master workbook copies section 19a of this mitigation workbook into FromMitigation (the activated .xlsb in active_workbooks, else the .xlsx in excel_ai\mitigation)
A14: File used by the last update | B14: none (shipped values)
A15: Last update | B15: shipped: values of CPAT-AI-Mitigation_latest.xlsx v1.2.0
A16: Country (Settings C4) | B16: =CtryCode -> EGY
A17: Calculation | B17: Shipped with its values, manual calculation: F9 recalculates; the Master workbook activates it
A19: Contents
A20: Tab | B20: Content
A21: Cover | B21: This page: what the module is, the link to the mitigation workbook
A22: ScenarioDefinition | B22: The distribution settings of each scenario (the other rows, set in the mitigation workbook, are hidden)
A23: FromMaster | B23: What the Master workbook wrote here (activation, data source): values
A24: FromMitigation | B24: The inputs from Mitigation (section 19a of the mitigation workbook): values, refreshed by the Master workbook (Update Distribution from Mitigation)
A25: Distribution | B25: The model: household incidence by decile in the analysis year, one column group per scenario
A26: Constants and Mappings | B26: Settings, constants, mappings and the data step of the mitigation workbook (those Mitigation reads are values here)
A27: DistMapping ... WEO | B27: The data tabs: mappings, input-output table, household survey, elasticities, ASPIRE, cooking fuels, GDP ratios, WEO
A29: Limits
B30: The data tabs and the Settings lookups are those of the prototype v1.2.0 (Egypt). Another country needs its own data tabs; its Mitigation inputs come from the mitigation workbook of that country.
B31: The scenario columns of ScenarioDefinition must carry the scenario numbers of the mitigation workbook (FromMitigation row 5).
A33: Version log
A34: Version | B34: Change | C34: Date
A35: 0.1.0 | B35: First standalone module, cut from the mitigation prototype v1.2.0: its Distribution and FromMitigation tabs, the distribution data tabs, the distribution rows of ScenarioDefinition and Settings. Inputs from Mitigation by the button Update from Mitigation (section 19a, defined name ExportDistn). | C35: 2026-10-22
A36: 0.1.1 | B36: Cut from the mitigation prototype v1.2.0: ScenarioDefinition on the rows of legacy 465 with a complete set of names (bug L137, issue I87); the mitigation workbook is looked for in permalink/ too; file named _v0.1.1 at the top of excel_ai/ (NORMS 5a). | C36: 2026-10-28
A37: 0.1.2 | B37: Cut from the mitigation prototype v1.2.0 (combustion emission factors as legacy, issue I98; data problems as issues). | C37: 2026-10-29
A38: 0.1.3 | B38: Cut from the mitigation prototype v1.2.0 (remaining functionality, reverts to legacy, data from legacy 465, last historical price year 2024); the Distribution method unchanged. | C38: 2026-10-29
A39: 0.1.4 | B39: Cut from the mitigation prototype v1.2.0: bug M22 fixed (found by Coded CPAT): the 25th/75th percentile recycling rows (hrec) add the public investment amount per person (pui of the sample, LCU), not its % row. | C39: 2026-10-29
A40: 1.0.0 | B40: First full release (user 2026-10-29), cut from the mitigation prototype v1.2.0: Distribution 0.1.4 as released. Replicated number for number by Coded CPAT 1.0.0p1.0. | C40: 2026-10-29
A41: 1.0.2 | B41: Cut from the mitigation prototype v1.2.0 (version aligned with Mitigation and Coded CPAT; ScenarioDefinition has the input row ModelForm). The Distribution method unchanged. | C41: 2026-10-29
A42: 1.0.3 | B42: Cut from the mitigation prototype v1.2.0. Update from Mitigation also looks in permalink_countryeditable\ (next to this workbook and one folder up) before permalink\. The Distribution method unchanged. | C42: 2026-10-29
A43: 1.0.4 | B43: Cut from the mitigation prototype v1.2.0 (outputs tab MTOutputs in the legacy layout); versions aligned. The Distribution method unchanged. | C43: 2026-10-29
A44: 1.1.0 | B44: Cut from the mitigation prototype v1.2.0: data edition Public01 (perturbed proprietary tables); Update from Mitigation looks next to this workbook, then in active_workbooks\ (one or two folders up). The Distribution method unchanged. | C44: 2026-10-30
A45: 1.2.0 | B45: Renamed CPAT-AI-Distribution (user 2026-10-31); cut from a full build of the mitigation workbook v1.2.0 (which no longer holds Distribution); .xlsx without macros: the Master workbook activates it and updates FromMitigation; tab FromMaster. The Distribution method and values unchanged. | C45: 2026-10-31

Sheet ScenarioDefinition
B1: MTInputs template - row structure copied exactly from legacy CPAT MTInputs (CPAT 1.0pre_465) | J1: Distribution module: only the distribution rows are shown (the other rows are set in the mitigation workbook). Scenario numbers (row 5) as in the mitigation workbook.
B2: Do not insert/delete rows. Columns D:E are hidden placeholders (MT values, Dashboard values). | H2: Short name (chart legends) | J2: Base | K2: CP20 | L2: CP20-b | M2: PkgA | N2: PkgB | O2: CP50
B3: Rows must match legacy 465 exactly. Column H: the names of the codes map (tab Inputs; legacy name kept there). See NORMS.md section 4. | J3: Scenario columns: short name in row 2, number in row 5, name in row 6; red = changed from the template value. J = baseline, K = live policy scenario (Mitigation group 2). | L3: Scenario definitions: row 4 Run? = Yes for the batch run (the Master workbook copies each into column K, runs it and stores the results). Copy the last definition one column to the right to add one.
J4: Baseline (stored once) | K4: Live (batch target) | L4: Yes | M4: Yes | N4: Yes | O4: Yes
C5: FALSE | D5: <-- Should normally be "FALSE"! | J5: 1 | K5: =J5+1 -> 2 | L5: =K5+1 -> 3 | M5: =L5+1 -> 4 | N5: =M5+1 -> 5 | O5: =N5+1 -> 6
D6: 6 | J6: Baseline (no carbon price) | K6: Carbon price $20/tCO2 from 2027 | L6: Carbon price $20/tCO2 from 2027 | M6: Package A: carbon tax to $50 by 2030 + feebates (transport, industry) | N6: Package B: ETS on power and industry (cap -5% 2027 to -20% 2035) + carbon tax $25 elsewhere | O6: Carbon price $50/tCO2 from 2027
B7: Parameters | C7: unit | D7: MT values | E7: "Dashboard" values | F7: Used for calculation | G7: Defaults | H7: NameOfParameter | J7: Used for calculation | K7: Used for calculation | L7: Used for calculation | M7: Used for calculation | N7: Used for calculation | O7: Used for calculation
B8: Country | F8: Egypt | G8: Egypt | H8: Countryname | J8: Egypt | K8: Egypt | L8: Egypt | M8: Egypt | N8: Egypt | O8: Egypt
B9: Scenario identification
B10: Scenario ID | C10: # | F10: N/A | G10: N/A | H10: MSTScenarioID | J10: =J$5 -> 1 | K10: =K$5 -> 2 | L10: =L$5 -> 3 | M10: =M$5 -> 4 | N10: =N$5 -> 5 | O10: =O$5 -> 6
B11: Scenario status | C11: switch | F11: N/A | G11: N/A | H11: ScenarioStatus | J11: N/A | K11: N/A | L11: N/A | M11: N/A | N11: N/A | O11: N/A
B12: Scenario name | C12: name | F12: N/A | G12: N/A | H12: ScenarioName | J12: =J$6 -> Baseline (no carbon price) | K12: =K$6 -> Carbon price $20/tCO2 from 2027 | L12: =L$6 -> Carbon price $20/tCO2 from 2027 | M12: =M$6 -> Package A: carbon tax to $50 by 2030 + feebates (transport, industry) | N12: =N$6 -> Package B: ETS on power and industry (cap -5% 2027 to -20% 2035) + carbon tax $25 elsewhere | O12: =O$6 -> Carbon price $50/tCO2 from 2027
B13: Chosen policy | C13: switch | F13: - Carbon tax | G13: - Carbon tax | H13: ScenarioSelected | J13: - Carbon tax | K13: - Carbon tax | L13: - Carbon tax | M13: - Carbon tax | N13: - Carbon tax | O13: - Carbon tax
B14: Scenario status for macro | C14: # | F14: N/A | G14: N/A | H14: ScenarioStatusMacro | J14: N/A | K14: N/A | L14: N/A | M14: N/A | N14: N/A | O14: N/A
B15: Scenario parameters override? | C15: # | F15: N/A | G15: N/A | H15: ScenarioParamOverride | J15: N/A | K15: N/A | L15: N/A | M15: N/A | N15: N/A | O15: N/A
B16: CPAT-side parameters override? | C16: switch | F16: Manual* | G16: Manual* | H16: CPATDefaultsOrUserDefined | J16: Manual* | K16: Manual* | L16: Manual* | M16: Manual* | N16: Manual* | O16: Manual*
B17: Carbon pricing: main inputs
A18: X | B18: Carbon pricing start year | C18: year | F18: 2026 | G18: 2027 | H18: CPIntro | J18: 2027 | K18: 2027 | L18: 2027 | M18: 2027 | N18: 2027 | O18: 2027
A19: X | B19: Starting carbon price | C19: nom. USD/tCO2 | F19: 0 | G19: 20 | H19: CPLevelStart | J19: 0 | K19: 20 | L19: 20 | M19: 10 | N19: 25 | O19: 50
B20: Target level of carbon price | C20: nom. USD/tCO2 | F20: 50 | G20: 50 | H20: CPLevelTarget | J20: 0 | K20: 20 | L20: 20 | M20: 50 | N20: 25 | O20: 50
A21: X | B21: Year to reach target level | C21: year | F21: 2030 | G21: 2035 | H21: CPOutro | J21: 2030 | K21: 2030 | L21: 2030 | M21: 2030 | N21: 2030 | O21: 2030
B22: Carbon pricing: fuel coverage
B23: Apply tax to coal? | C23: switch | F23: TRUE | G23: TRUE | H23: MCovCoa | J23: TRUE | K23: TRUE | L23: TRUE | M23: TRUE | N23: TRUE | O23: TRUE
B24: Apply tax to natural gas? | C24: switch | F24: TRUE | G24: TRUE | H24: MCovNga | J24: TRUE | K24: TRUE | L24: TRUE | M24: TRUE | N24: TRUE | O24: TRUE
B25: Apply tax to gasoline? | C25: switch | F25: TRUE | G25: TRUE | H25: MCovGso | J25: TRUE | K25: TRUE | L25: TRUE | M25: TRUE | N25: TRUE | O25: TRUE
B26: Apply tax to diesel? | C26: switch | F26: TRUE | G26: TRUE | H26: MCovDie | J26: TRUE | K26: TRUE | L26: TRUE | M26: TRUE | N26: TRUE | O26: TRUE
B27: Apply tax to LPG? | C27: switch | F27: TRUE | G27: TRUE | H27: MCovLpg | J27: TRUE | K27: TRUE | L27: TRUE | M27: TRUE | N27: TRUE | O27: TRUE
B28: Apply tax to kerosene? | C28: switch | F28: TRUE | G28: TRUE | H28: MCovKer | J28: TRUE | K28: TRUE | L28: TRUE | M28: TRUE | N28: TRUE | O28: TRUE
B29: Apply tax to non-road oil products? | C29: switch | F29: TRUE | G29: TRUE | H29: MCovOop | J29: TRUE | K29: TRUE | L29: TRUE | M29: TRUE | N29: TRUE | O29: TRUE
B30: Carbon pricing: sector coverage
B31: Apply tax to power sector? | C31: switch | F31: TRUE | G31: TRUE | H31: MCovPow | J31: TRUE | K31: TRUE | L31: TRUE | M31: TRUE | N31: TRUE | O31: TRUE
B32: Apply tax to road transportation? | C32: switch | F32: TRUE | G32: TRUE | H32: MCovRod | J32: TRUE | K32: TRUE | L32: TRUE | M32: TRUE | N32: TRUE | O32: TRUE
B33: Apply tax to rail transportation? | C33: switch | F33: TRUE | G33: TRUE | H33: MCovRal | J33: TRUE | K33: TRUE | L33: TRUE | M33: TRUE | N33: TRUE | O33: TRUE
B34: Apply tax to domestic aviation? | C34: switch | F34: TRUE | G34: TRUE | H34: MCovAvi | J34: TRUE | K34: TRUE | L34: TRUE | M34: TRUE | N34: TRUE | O34: TRUE
B35: Apply tax to domestic shipping? | C35: switch | F35: TRUE | G35: TRUE | H35: MCovNav | J35: TRUE | K35: TRUE | L35: TRUE | M35: TRUE | N35: TRUE | O35: TRUE
B36: Apply tax to residential sector? | C36: switch | F36: TRUE | G36: TRUE | H36: MCovRes | J36: TRUE | K36: TRUE | L36: TRUE | M36: TRUE | N36: TRUE | O36: TRUE
B37: Apply tax to food & forestry? | C37: switch | F37: TRUE | G37: TRUE | H37: MCovFoo | J37: TRUE | K37: TRUE | L37: TRUE | M37: TRUE | N37: TRUE | O37: TRUE
B38: Apply tax to services (private / public)? | C38: switch | F38: TRUE | G38: TRUE | H38: MCovSrv | J38: TRUE | K38: TRUE | L38: TRUE | M38: TRUE | N38: TRUE | O38: TRUE
B39: Apply tax to mining & chemicals? | C39: switch | F39: TRUE | G39: TRUE | H39: MCovMch | J39: TRUE | K39: TRUE | L39: TRUE | M39: TRUE | N39: TRUE | O39: TRUE
B40: Apply tax to iron and steel? | C40: switch | F40: TRUE | G40: TRUE | H40: MCovIrn | J40: TRUE | K40: TRUE | L40: TRUE | M40: TRUE | N40: TRUE | O40: TRUE
...

Sheet FromMaster
A2: FromMaster - what the Master workbook wrote here (activation, data source); values
A3: Written by the macros of the Master workbook (CPAT-AI-Master_UserGuide.xlsm, active_workbooks); read by the Cover. Values only: the module has no macros and no link to another file.
A5: Name | B5: Item | C5: Value
A6: FMMaster | B6: Master workbook (writes this tab) | C6: CPAT-AI-Master_UserGuide.xlsm
A7: FMVersion | B7: Version of the Master that last wrote here | C7: none (shipped)
A8: FMActivated | B8: Activated (formulas to the last year, recalculated, saved as .xlsb) | C8: not activated: formulas to 2035
A9: FMSource | B9: Data source of the linked tables | C9: Embedded (shipped data, no update)
A10: FMRows | B10: Rows loaded (Country = the country of MTInputs; All countries) | C10: Country
A11: FMPath | B11: File or URL of the data source

Sheet FromMitigation
H1: Year | K1: Scenario: output code | L1: 2022 | M1: 2023 | N1: 2024 | O1: 2025 | P1: 2026 | Q1: 2027 | R1: 2028 | S1: 2029 | T1: 2030 | U1: 2031 | V1: 2032 | W1: 2033 | X1: 2034 | Y1: 2035 | Z1: 2036 | AA1: 2037 | AB1: 2038 | AC1: 2039 | AD1: 2040 | AE1: 2041 | AG1: Scenario: output code | AH1: 2022 | AI1: 2023 | AJ1: 2024 | AK1: 2025 | AL1: 2026 | AM1: 2027 | AN1: 2028 | AO1: 2029 | AP1: 2030 | AQ1: 2031 | AR1: 2032 | AS1: 2033 | AT1: 2034 | AU1: 2035 | AV1: 2036 | AW1: 2037 | AX1: 2038 | AY1: 2039 | AZ1: 2040 | BA1: 2041
A2: FromMitigation - the inputs of the distribution module from Mitigation (section 19a)
H5: Scenario number | K5: 1 | L5: 1 | M5: 1 | N5: 1 | O5: 1 | P5: 1 | Q5: 1 | R5: 1 | S5: 1 | T5: 1 | U5: 1 | V5: 1 | W5: 1 | X5: 1 | Y5: 1 | Z5: 1 | AA5: 1 | AB5: 1 | AC5: 1 | AD5: 1 | AE5: 1 | AG5: 2 | AH5: 2 | AI5: 2 | AJ5: 2 | AK5: 2 | AL5: 2 | AM5: 2 | AN5: 2 | AO5: 2 | AP5: 2 | AQ5: 2 | AR5: 2 | AS5: 2 | AT5: 2 | AU5: 2 | AV5: 2 | AW5: 2 | AX5: 2 | AY5: 2 | AZ5: 2 | BA5: 2
A7: Variable | B7: Fuel | C7: Sector | D7: Scale to base unit | E7: Base unit | H7: Description | I7: Unit (Mitigation) | J7: Source
A8: gdp.lcu | B8: all | C8: all | D8: 1000000000 | E8: LCU | H8: Real GDP, baseline (local currency bn, sheet WEO; legacy row 464; v0.3.13) | I8: LCU bn | J8: Mitigation section 19a | K8: egy.mit.gdp.lcu.all.all.1 | L8: 7842.5 | M8: 8137.4 | N8: 8332.6 | O8: 8698.6 | P8: 9067.395 | Q8: 9505.2793 | R8: 10031.427 | S8: 10555.73 | T8: 11066.825 | U8: 11596.786 | V8: 12145.963 | W8: 12714.692 | X8: 13303.295 | Y8: 13912.077 | Z8: 14541.324 | AA8: 15191.305 | AB8: 15862.267 | AC8: 16554.434 | AD8: 17268.008 | AE8: 18003.163 | AG8: egy.mit.gdp.lcu.all.all.2 | AH8: 7842.5 | AI8: 8137.4 | AJ8: 8332.6 | AK8: 8698.6 | AL8: 9067.395 | AM8: 9505.2793 | AN8: 10031.427 | AO8: 10555.73 | AP8: 11066.825 | AQ8: 11596.786 | AR8: 12145.963 | AS8: 12714.692 | AT8: 13303.295 | AU8: 13912.077 | AV8: 14541.324 | AW8: 15191.305 | AX8: 15862.267 | AY8: 16554.434 | AZ8: 17268.008 | BA8: 18003.163
A9: xr | B9: all | C9: all | D9: 1 | H9: Exchange rate implied by real GDP: local currency per USD, constant in real terms (v0.3.13) | I9: LCU/USD | J9: Mitigation section 19a | K9: egy.mit.xr.all.all.1 | L9: 14.338056 | M9: 14.338056 | N9: 14.338056 | O9: 14.338056 | P9: 14.338056 | Q9: 14.338056 | R9: 14.338056 | S9: 14.338056 | T9: 14.338056 | U9: 14.338056 | V9: 14.338056 | W9: 14.338056 | X9: 14.338056 | Y9: 14.338056 | Z9: 14.338056 | AA9: 14.338056 | AB9: 14.338056 | AC9: 14.338056 | AD9: 14.338056 | AE9: 14.338056 | AG9: egy.mit.xr.all.all.2 | AH9: 14.338056 | AI9: 14.338056 | AJ9: 14.338056 | AK9: 14.338056 | AL9: 14.338056 | AM9: 14.338056 | AN9: 14.338056 | AO9: 14.338056 | AP9: 14.338056 | AQ9: 14.338056 | AR9: 14.338056 | AS9: 14.338056 | AT9: 14.338056 | AU9: 14.338056 | AV9: 14.338056 | AW9: 14.338056 | AX9: 14.338056 | AY9: 14.338056 | AZ9: 14.338056 | BA9: 14.338056
A10: pop | B10: all | C10: all | D10: 1000 | E10: persons | H10: Population | All sectors | All fuels | I10: thousand | J10: Mitigation section 19a | K10: egy.mit.pop.all.all.1 | L10: 111743.37 | M10: 113493.13 | N10: 116538.26 | O10: 118365.99 | P10: 120101.18 | Q10: 121847.62 | R10: 123608.46 | S10: 125373.05 | T10: 127139.32 | U10: 128912.25 | V10: 130695.08 | W10: 132485.61 | X10: 134287.84 | Y10: 136097.22 | Z10: 137913.26 | AA10: 139738.7 | AB10: 141565.83 | AC10: 143393.26 | AD10: 145213.65 | AE10: 147018.56 | AG10: egy.mit.pop.all.all.2 | AH10: 111743.37 | AI10: 113493.13 | AJ10: 116538.26 | AK10: 118365.99 | AL10: 120101.18 | AM10: 121847.62 | AN10: 123608.46 | AO10: 125373.05 | AP10: 127139.32 | AQ10: 128912.25 | AR10: 130695.08 | AS10: 132485.61 | AT10: 134287.84 | AU10: 136097.22 | AV10: 137913.26 | AW10: 139738.7 | AX10: 141565.83 | AY10: 143393.26 | AZ10: 145213.65 | BA10: 147018.56
A11: rnew | B11: all | C11: all | D11: 1000000 | E11: USD | H11: Revenue from new policies (carbon tax, excise, auctioned ETS, VAT on them) | All sectors | All fuels | I11: USD m real | J11: Mitigation section 19a | K11: egy.mit.rnew.tot.tot.1 | L11: 0 | M11: 0 | N11: 0 | O11: 0 | P11: 0 | Q11: 0 | R11: 0 | S11: 0 | T11: 0 | U11: 0 | V11: 0 | W11: 0 | X11: 0 | Y11: 0 | Z11: 0 | AA11: 0 | AB11: 0 | AC11: 0 | AD11: 0 | AE11: 0 | AG11: egy.mit.rnew.tot.tot.2 | AH11: 0 | AI11: 0 | AJ11: 0 | AK11: 0 | AL11: 0 | AM11: 4963.4827 | AN11: 4909.8102 | AO11: 5096.3675 | AP11: 5190.4642 | AQ11: 5272.9227 | AR11: 5320.241 | AS11: 5439.2411 | AT11: 5531.8505 | AU11: 5641.1717 | AV11: 5752.113 | AW11: 5867.3621 | AX11: 5981.4069 | AY11: 6096.0896 | AZ11: 6209.0057 | BA11: 6323.0646
A12: atp | B12: coa | C12: res | D12: 1 | H12: After-tax price | Residential | Coal | I12: USD/GJ real | J12: Mitigation section 19a | K12: egy.mit.atp.res.coa.1 | L12: 23.57658 | M12: 15.452973 | N12: 14.483227 | O12: 13.293239 | P12: 13.948916 | Q12: 14.09682 | R12: 14.026689 | S12: 13.951483 | T12: 13.870992 | U12: 13.793315 | V12: 13.793315 | W12: 13.793315 | X12: 13.793315 | Y12: 13.793315 | Z12: 13.793315 | AA12: 13.793315 | AB12: 13.793315 | AC12: 13.793315 | AD12: 13.793315 | AE12: 13.793315 | AG12: egy.mit.atp.res.coa.2 | AH12: 23.57658 | AI12: 15.452973 | AJ12: 14.483227 | AK12: 13.293239 | AL12: 13.948916 | AM12: 16.237272 | AN12: 16.167141 | AO12: 16.091935 | AP12: 16.011444 | AQ12: 15.933767 | AR12: 15.933767 | AS12: 15.933767 | AT12: 15.933767 | AU12: 15.933767 | AV12: 15.933767 | AW12: 15.933767 | AX12: 15.933767 | AY12: 15.933767 | AZ12: 15.933767 | BA12: 15.933767
A13: atp | B13: nga | C13: res | D13: 1 | H13: After-tax price | Residential | Natural gas | I13: USD/GJ real | J13: Mitigation section 19a | K13: egy.mit.atp.res.nga.1 | L13: 4.9564885 | M13: 2.7348469 | N13: 1.7971601 | O13: 1.7971601 | P13: 1.7971601 | Q13: 1.7971601 | R13: 1.7971601 | S13: 1.7971601 | T13: 1.7971601 | U13: 1.7971601 | V13: 1.7971601 | W13: 1.7971601 | X13: 1.7971601 | Y13: 1.7971601 | Z13: 1.7971601 | AA13: 1.7971601 | AB13: 1.7971601 | AC13: 1.7971601 | AD13: 1.7971601 | AE13: 1.7971601 | AG13: egy.mit.atp.res.nga.2 | AH13: 4.9564885 | AI13: 2.7348469 | AJ13: 1.7971601 | AK13: 1.7971601 | AL13: 1.7971601 | AM13: 2.9081833 | AN13: 2.9081833 | AO13: 2.9081833 | AP13: 2.9081833 | AQ13: 2.9081833 | AR13: 2.9081833 | AS13: 2.9081833 | AT13: 2.9081833 | AU13: 2.9081833 | AV13: 2.9081833 | AW13: 2.9081833 | AX13: 2.9081833 | AY13: 2.9081833 | AZ13: 2.9081833 | BA13: 2.9081833
A14: atp | B14: oop | C14: res | D14: 1 | H14: After-tax price | Residential | Other oil products | I14: USD/GJ real | J14: Mitigation section 19a | K14: egy.mit.atp.res.oop.1 | L14: 4.8634416 | M14: 4.3984443 | N14: 4.185618 | O14: 4.185618 | P14: 4.185618 | Q14: 4.185618 | R14: 4.185618 | S14: 4.185618 | T14: 4.185618 | U14: 4.185618 | V14: 4.185618 | W14: 4.185618 | X14: 4.185618 | Y14: 4.185618 | Z14: 4.185618 | AA14: 4.185618 | AB14: 4.185618 | AC14: 4.185618 | AD14: 4.185618 | AE14: 4.185618 | AG14: egy.mit.atp.res.oop.2 | AH14: 4.8634416 | AI14: 4.3984443 | AJ14: 4.185618 | AK14: 4.185618 | AL14: 4.185618 | AM14: 5.7127771 | AN14: 5.7127771 | AO14: 5.7127771 | AP14: 5.7127771 | AQ14: 5.7127771 | AR14: 5.7127771 | AS14: 5.7127771 | AT14: 5.7127771 | AU14: 5.7127771 | AV14: 5.7127771 | AW14: 5.7127771 | AX14: 5.7127771 | AY14: 5.7127771 | AZ14: 5.7127771 | BA14: 5.7127771
A15: atp | B15: gso | C15: res | D15: 1 | H15: After-tax price | Residential | Gasoline | I15: USD/GJ real | J15: Mitigation section 19a | K15: egy.mit.atp.res.gso.1 | L15: 18.107131 | M15: 11.328675 | N15: 9.1450408 | O15: 9.1450408 | P15: 9.1450408 | Q15: 9.1450408 | R15: 9.1450408 | S15: 9.1450408 | T15: 9.1450408 | U15: 9.1450408 | V15: 9.1450408 | W15: 9.1450408 | X15: 9.1450408 | Y15: 9.1450408 | Z15: 9.1450408 | AA15: 9.1450408 | AB15: 9.1450408 | AC15: 9.1450408 | AD15: 9.1450408 | AE15: 9.1450408 | AG15: egy.mit.atp.res.gso.2 | AH15: 18.107131 | AI15: 11.328675 | AJ15: 9.1450408 | AK15: 9.1450408 | AL15: 9.1450408 | AM15: 10.510026 | AN15: 10.510026 | AO15: 10.510026 | AP15: 10.510026 | AQ15: 10.510026 | AR15: 10.510026 | AS15: 10.510026 | AT15: 10.510026 | AU15: 10.510026 | AV15: 10.510026 | AW15: 10.510026 | AX15: 10.510026 | AY15: 10.510026 | AZ15: 10.510026 | BA15: 10.510026
A16: atp | B16: die | C16: res | D16: 1 | H16: After-tax price | Residential | Diesel | I16: USD/GJ real | J16: Mitigation section 19a | K16: egy.mit.atp.res.die.1 | L16: 11.228295 | M16: 7.7491704 | N16: 6.8266892 | O16: 6.8266892 | P16: 6.8266892 | Q16: 6.8266892 | R16: 6.8266892 | S16: 6.8266892 | T16: 6.8266892 | U16: 6.8266892 | V16: 6.8266892 | W16: 6.8266892 | X16: 6.8266892 | Y16: 6.8266892 | Z16: 6.8266892 | AA16: 6.8266892 | AB16: 6.8266892 | AC16: 6.8266892 | AD16: 6.8266892 | AE16: 6.8266892 | AG16: egy.mit.atp.res.die.2 | AH16: 11.228295 | AI16: 7.7491704 | AJ16: 6.8266892 | AK16: 6.8266892 | AL16: 6.8266892 | AM16: 8.2881426 | AN16: 8.2881426 | AO16: 8.2881426 | AP16: 8.2881426 | AQ16: 8.2881426 | AR16: 8.2881426 | AS16: 8.2881426 | AT16: 8.2881426 | AU16: 8.2881426 | AV16: 8.2881426 | AW16: 8.2881426 | AX16: 8.2881426 | AY16: 8.2881426 | AZ16: 8.2881426 | BA16: 8.2881426
A17: atp | B17: ker | C17: res | D17: 1 | H17: After-tax price | Residential | Kerosene | I17: USD/GJ real | J17: Mitigation section 19a | K17: egy.mit.atp.res.ker.1 | L17: 10.553589 | M17: 6.8465155 | N17: 7.0761974 | O17: 7.0761974 | P17: 7.0761974 | Q17: 7.0761974 | R17: 7.0761974 | S17: 7.0761974 | T17: 7.0761974 | U17: 7.0761974 | V17: 7.0761974 | W17: 7.0761974 | X17: 7.0761974 | Y17: 7.0761974 | Z17: 7.0761974 | AA17: 7.0761974 | AB17: 7.0761974 | AC17: 7.0761974 | AD17: 7.0761974 | AE17: 7.0761974 | AG17: egy.mit.atp.res.ker.2 | AH17: 10.553589 | AI17: 6.8465155 | AJ17: 7.0761974 | AK17: 7.0761974 | AL17: 7.0761974 | AM17: 8.4411829 | AN17: 8.4411829 | AO17: 8.4411829 | AP17: 8.4411829 | AQ17: 8.4411829 | AR17: 8.4411829 | AS17: 8.4411829 | AT17: 8.4411829 | AU17: 8.4411829 | AV17: 8.4411829 | AW17: 8.4411829 | AX17: 8.4411829 | AY17: 8.4411829 | AZ17: 8.4411829 | BA17: 8.4411829
A18: atp | B18: lpg | C18: res | D18: 1 | H18: After-tax price | Residential | LPG | I18: USD/GJ real | J18: Mitigation section 19a | K18: egy.mit.atp.res.lpg.1 | L18: 5.9267651 | M18: 3.4733342 | N18: 4.0682684 | O18: 4.0682684 | P18: 4.0682684 | Q18: 4.0682684 | R18: 4.0682684 | S18: 4.0682684 | T18: 4.0682684 | U18: 4.0682684 | V18: 4.0682684 | W18: 4.0682684 | X18: 4.0682684 | Y18: 4.0682684 | Z18: 4.0682684 | AA18: 4.0682684 | AB18: 4.0682684 | AC18: 4.0682684 | AD18: 4.0682684 | AE18: 4.0682684 | AG18: egy.mit.atp.res.lpg.2 | AH18: 5.9267651 | AI18: 3.4733342 | AJ18: 4.0682684 | AK18: 4.0682684 | AL18: 4.0682684 | AM18: 5.4341499 | AN18: 5.4341499 | AO18: 5.4341499 | AP18: 5.4341499 | AQ18: 5.4341499 | AR18: 5.4341499 | AS18: 5.4341499 | AT18: 5.4341499 | AU18: 5.4341499 | AV18: 5.4341499 | AW18: 5.4341499 | AX18: 5.4341499 | AY18: 5.4341499 | AZ18: 5.4341499 | BA18: 5.4341499
A19: rp | B19: ecy | C19: res | D19: 1 | H19: End-user electricity price | Residential | Electricity | I19: USD/kWh real | J19: Mitigation section 19a | K19: egy.mit.rp.res.ecy.1 | L19: 0.061135555 | M19: 0.053218541 | N19: 0.045128065 | O19: 0.043973478 | P19: 0.043981 | Q19: 0.044425438 | R19: 0.04456749 | S19: 0.045253725 | T19: 0.045925822 | U19: 0.046681109 | V19: 0.045438885 | W19: 0.044415971 | X19: 0.043400832 | Y19: 0.042454429 | Z19: 0.041569389 | AA19: 0.040741982 | AB19: 0.039966149 | AC19: 0.039233924 | AD19: 0.038540291 | AE19: 0.037879595 | AG19: egy.mit.rp.res.ecy.2 | AH19: 0.061135555 | AI19: 0.053218541 | AJ19: 0.045128065 | AK19: 0.043974813 | AL19: 0.043984458 | AM19: 0.05363388 | AN19: 0.053578425 | AO19: 0.055133487 | AP19: 0.054395535 | AQ19: 0.054794228 | AR19: 0.053041335 | AS19: 0.051740034 | AT19: 0.050368468 | AU19: 0.049104981 | AV19: 0.047944449 | AW19: 0.046866885 | AX19: 0.045860166 | AY19: 0.044917232 | AZ19: 0.044028885 | BA19: 0.043189636
A20: rpn | B20: coa | C20: ind | D20: 1 | H20: Retail price incl. new taxes and subsidies (fuel-use weighted average of the after-tax prices atp of the subsectors priced by the block; rpb where they use none) | Industry | Coal | I20: USD/GJ real | J20: Mitigation section 19a | K20: egy.mit.rpn.ind.coa.1 | L20: 11.251347 | M20: 8.7773563 | N20: 7.5715284 | O20: 6.8162015 | P20: 7.2323827 | Q20: 7.3262627 | R20: 7.2817484 | S20: 7.234012 | T20: 7.1829218 | U20: 7.1336176 | V20: 7.1336176 | W20: 7.1336176 | X20: 7.1336176 | Y20: 7.1336176 | Z20: 7.1336176 | AA20: 7.1336176 | AB20: 7.1336176 | AC20: 7.1336176 | AD20: 7.1336176 | AE20: 7.1336176 | AG20: egy.mit.rpn.ind.coa.2 | AH20: 11.251347 | AI20: 8.7773563 | AJ20: 7.5715284 | AK20: 6.8162015 | AL20: 7.2323827 | AM20: 9.3173436 | AN20: 9.2728292 | AO20: 9.2250929 | AP20: 9.1740026 | AQ20: 9.1246984 | AR20: 9.1246984 | AS20: 9.1246984 | AT20: 9.1246984 | AU20: 9.1246984 | AV20: 9.1246984 | AW20: 9.1246984 | AX20: 9.1246984 | AY20: 9.1246984 | AZ20: 9.1246984 | BA20: 9.1246984
A21: rpn | B21: nga | C21: ind | D21: 1 | H21: Retail price incl. new taxes and subsidies (fuel-use weighted average of the after-tax prices atp of the subsectors priced by the block; rpb where they use none) | Industry | Natural gas | I21: USD/GJ real | J21: Mitigation section 19a | K21: egy.mit.rpn.ind.nga.1 | L21: 4.899795 | M21: 5.1184551 | N21: 4.8850072 | O21: 4.8850072 | P21: 4.8850072 | Q21: 4.8850072 | R21: 4.8850072 | S21: 4.8850072 | T21: 4.8850072 | U21: 4.8850072 | V21: 4.8850072 | W21: 4.8850072 | X21: 4.8850072 | Y21: 4.8850072 | Z21: 4.8850072 | AA21: 4.8850072 | AB21: 4.8850072 | AC21: 4.8850072 | AD21: 4.8850072 | AE21: 4.8850072 | AG21: egy.mit.rpn.ind.nga.2 | AH21: 4.899795 | AI21: 5.1184551 | AJ21: 4.8850072 | AK21: 4.8850072 | AL21: 4.8850072 | AM21: 5.9960304 | AN21: 5.9960304 | AO21: 5.9960304 | AP21: 5.9960304 | AQ21: 5.9960304 | AR21: 5.9960304 | AS21: 5.9960304 | AT21: 5.9960304 | AU21: 5.9960304 | AV21: 5.9960304 | AW21: 5.9960304 | AX21: 5.9960304 | AY21: 5.9960304 | AZ21: 5.9960304 | BA21: 5.9960304
A22: rpn | B22: oop | C22: all | D22: 1 | H22: Retail price incl. new taxes and subsidies (fuel-use weighted average of the after-tax prices atp of the subsectors priced by the block; rpb where they use none) | All sectors | Other oil products | I22: USD/GJ real | J22: Mitigation section 19a | K22: egy.mit.rpn.all.oop.1 | L22: 4.8634416 | M22: 4.3984443 | N22: 4.185618 | O22: 4.185618 | P22: 4.185618 | Q22: 4.185618 | R22: 4.185618 | S22: 4.185618 | T22: 4.185618 | U22: 4.185618 | V22: 4.185618 | W22: 4.185618 | X22: 4.185618 | Y22: 4.185618 | Z22: 4.185618 | AA22: 4.185618 | AB22: 4.185618 | AC22: 4.185618 | AD22: 4.185618 | AE22: 4.185618 | AG22: egy.mit.rpn.all.oop.2 | AH22: 4.8634416 | AI22: 4.3984443 | AJ22: 4.185618 | AK22: 4.185618 | AL22: 4.185618 | AM22: 5.6416126 | AN22: 5.641629 | AO22: 5.6416454 | AP22: 5.6416617 | AQ22: 5.641678 | AR22: 5.6416942 | AS22: 5.6417104 | AT22: 5.6417265 | AU22: 5.6417425 | AV22: 5.6417585 | AW22: 5.6417745 | AX22: 5.6417903 | AY22: 5.6418062 | AZ22: 5.641822 | BA22: 5.6418377
A23: rpn | B23: gso | C23: all | D23: 1 | H23: Retail price incl. new taxes and subsidies (fuel-use weighted average of the after-tax prices atp of the subsectors priced by the block; rpb where they use none) | All sectors | Gasoline | I23: USD/GJ real | J23: Mitigation section 19a | K23: egy.mit.rpn.all.gso.1 | L23: 18.107131 | M23: 11.328675 | N23: 9.1450408 | O23: 9.1450408 | P23: 9.1450408 | Q23: 9.1450408 | R23: 9.1450408 | S23: 9.1450408 | T23: 9.1450408 | U23: 9.1450408 | V23: 9.1450408 | W23: 9.1450408 | X23: 9.1450408 | Y23: 9.1450408 | Z23: 9.1450408 | AA23: 9.1450408 | AB23: 9.1450408 | AC23: 9.1450408 | AD23: 9.1450408 | AE23: 9.1450408 | AG23: egy.mit.rpn.all.gso.2 | AH23: 18.107131 | AI23: 11.328675 | AJ23: 9.1450408 | AK23: 9.1450408 | AL23: 9.1450408 | AM23: 10.462698 | AN23: 10.462698 | AO23: 10.462698 | AP23: 10.462698 | AQ23: 10.462698 | AR23: 10.462698 | AS23: 10.462698 | AT23: 10.462698 | AU23: 10.462698 | AV23: 10.462698 | AW23: 10.462698 | AX23: 10.462698 | AY23: 10.462698 | AZ23: 10.462698 | BA23: 10.462698
... A35: pav.sp | B35: ecy | C35: all | D35: 1 | H35: Spending on the fuel at after-tax prices (sum over subsectors of atp x fuel use; electricity: rp x consumption, USD m; all energy: USD m) | All sectors | Electricity | I35: USD/GJ x ktoe | J35: Mitigation section 19a | K35: egy.mit.pav.sp.all.ecy.1 | L35: 10352.346 | M35: 9688.0843 | N35: 9207.6753 | O35: 10169.533 | P35: 10668.489 | Q35: 11204.691 | R35: 11691.537 | S35: 12352.557 | T35: 12899.921 | U35: 13495.427 | V35: 13558.86 | W35: 13925.299 | X35: 14265.044 | Y35: 14631.423 | Z35: 15007.038 | AA35: 15392.654 | AB35: 15787.422 | AC35: 16189.964 | AD35: 16600.333 | AE35: 17017.566 | AG35: egy.mit.pav.sp.all.ecy.2 | AH35: 10352.346 | AI35: 9688.0843 | AJ35: 9207.6753 | AK35: 10169.859 | AL35: 10669.173 | AM35: 13304.559 | AN35: 12657.872 | AO35: 13570.577 | AP35: 13707.44 | AQ35: 14416.214 | AR35: 14449.952 | AS35: 14854.099 | AT35: 15199.545 | AU35: 15579.015 | AV35: 15976.923 | AW35: 16392.108 | AX35: 16809.821 | AY35: 17233.534 | AZ35: 17656.294 | BA35: 18084.759

Sheet Distribution
A1: Variable | B1: Item | C1: Sample | D1: Param 1 | E1: Param 2 | H1: Description | I1: Unit | J1: Source | K1: Scenario: output code | L1: 0 | M1: 1 | N1: 2 | O1: 3 | P1: 4 | Q1: 5 | R1: 6 | S1: 7 | T1: 8 | U1: 9 | V1: 10 | X1: Scenario: output code | Y1: 0 | Z1: 1 | AA1: 2 | AB1: 3 | AC1: 4 | AD1: 5 | AE1: 6 | AF1: 7 | AG1: 8 | AH1: 9 | AI1: 10
A2: Distribution - household incidence of the scenario in the analysis year (deciles across)
A3: 0 | B3: Scenario and analysis year
H4: Scenario name (from MTInputs) | L4: =INDEX(ScenarioDefinition!$J$6:$AZ$6,MATCH(L$5,ScenarioDefinition!$J$5:$AZ$5,0)) -> Baseline (no carbon price) | W4: =IF(X$5=K$5,MAX(MAX(W$16:W$969),-MIN(W$16:W$969)),"") | Y4: =INDEX(ScenarioDefinition!$J$6:$AZ$6,MATCH(Y$5,ScenarioDefinition!$J$5:$AZ$5,0)) -> Carbon price $20/tCO2 from 2027
H5: Scenario number (MTInputs column) | K5: =COUNTIF($K$1:K$1,"Scenario*") -> 1 | L5: =K5 -> 1 | M5: =L5 -> 1 | N5: =M5 -> 1 | O5: =N5 -> 1 | P5: =O5 -> 1 | Q5: =P5 -> 1 | R5: =Q5 -> 1 | S5: =R5 -> 1 | ... V5: =U5 -> 1 | X5: =COUNTIF($K$1:X$1,"Scenario*") -> 2 | Y5: =X5 -> 2 | Z5: =Y5 -> 2 | AA5: =Z5 -> 2 | AB5: =AA5 -> 2 | AC5: =AB5 -> 2 | AD5: =AC5 -> 2 | AE5: =AD5 -> 2 | AF5: =AE5 -> 2 | ... AI5: =AH5 -> 2
H6: Position of the column group (LAMBDA test group included) | L6: =COUNTIF($K$1:K$1,"*output code") -> 1 | M6: =L6 -> 1 | N6: =M6 -> 1 | O6: =N6 -> 1 | P6: =O6 -> 1 | Q6: =P6 -> 1 | R6: =Q6 -> 1 | S6: =R6 -> 1 | T6: =S6 -> 1 | ... V6: =U6 -> 1 | Y6: =COUNTIF($K$1:X$1,"*output code") -> 2 | Z6: =Y6 -> 2 | AA6: =Z6 -> 2 | AB6: =AA6 -> 2 | AC6: =AB6 -> 2 | AD6: =AC6 -> 2 | AE6: =AD6 -> 2 | AF6: =AE6 -> 2 | AG6: =AF6 -> 2 | ... AI6: =AH6 -> 2
H7: Mitigation column of the analysis year, scenario 1 (group 1) | L7: =MATCH(L$12,FromMitigation!$K$1:$AF$1,0) -> 10 | M7: =L7 -> 10 | N7: =M7 -> 10 | O7: =N7 -> 10 | P7: =O7 -> 10 | Q7: =P7 -> 10 | R7: =Q7 -> 10 | S7: =R7 -> 10 | T7: =S7 -> 10 | ... V7: =U7 -> 10 | Y7: =MATCH(Y$12,FromMitigation!$K$1:$AF$1,0) -> 10 | Z7: =Y7 -> 10 | AA7: =Z7 -> 10 | AB7: =AA7 -> 10 | AC7: =AB7 -> 10 | AD7: =AC7 -> 10 | AE7: =AD7 -> 10 | AF7: =AE7 -> 10 | AG7: =AF7 -> 10 | ... AI7: =AH7 -> 10
H8: Mitigation column of the analysis year, this scenario group | L8: =L$7+(L$6-1)*MitGW -> 10 | M8: =L8 -> 10 | N8: =M8 -> 10 | O8: =N8 -> 10 | P8: =O8 -> 10 | Q8: =P8 -> 10 | R8: =Q8 -> 10 | S8: =R8 -> 10 | T8: =S8 -> 10 | ... V8: =U8 -> 10 | Y8: =Y$7+(Y$6-1)*MitGW -> 32 | Z8: =Y8 -> 32 | AA8: =Z8 -> 32 | AB8: =AA8 -> 32 | AC8: =AB8 -> 32 | AD8: =AC8 -> 32 | AE8: =AD8 -> 32 | AF8: =AE8 -> 32 | AG8: =AF8 -> 32 | ... AI8: =AH8 -> 32
H9: Statistic of the household survey (MTInputs QuantilesStatistic) | L9: =L$17 -> mean | M9: =L9 -> mean | N9: =M9 -> mean | O9: =N9 -> mean | P9: =O9 -> mean | Q9: =P9 -> mean | R9: =Q9 -> mean | S9: =R9 -> mean | T9: =S9 -> mean | ... V9: =U9 -> mean | Y9: =Y$17 -> mean | Z9: =Y9 -> mean | AA9: =Z9 -> mean | AB9: =AA9 -> mean | AC9: =AB9 -> mean | AD9: =AC9 -> mean | AE9: =AD9 -> mean | AF9: =AE9 -> mean | AG9: =AF9 -> mean | ... AI9: =AH9 -> mean
H10: Survey code: basket or decile (legacy HHSurvey code part) | L10: =IF(L$1=0,"bkt.","dec.") -> bkt. | M10: =IF(M$1=0,"bkt.","dec.") -> dec. | N10: =IF(N$1=0,"bkt.","dec.") -> dec. | O10: =IF(O$1=0,"bkt.","dec.") -> dec. | P10: =IF(P$1=0,"bkt.","dec.") -> dec. | Q10: =IF(Q$1=0,"bkt.","dec.") -> dec. | R10: =IF(R$1=0,"bkt.","dec.") -> dec. | S10: =IF(S$1=0,"bkt.","dec.") -> dec. | ... V10: =IF(V$1=0,"bkt.","dec.") -> dec. | Y10: =IF(Y$1=0,"bkt.","dec.") -> bkt. | Z10: =IF(Z$1=0,"bkt.","dec.") -> dec. | AA10: =IF(AA$1=0,"bkt.","dec.") -> dec. | AB10: =IF(AB$1=0,"bkt.","dec.") -> dec. | AC10: =IF(AC$1=0,"bkt.","dec.") -> dec. | AD10: =IF(AD$1=0,"bkt.","dec.") -> dec. | AE10: =IF(AE$1=0,"bkt.","dec.") -> dec. | AF10: =IF(AF$1=0,"bkt.","dec.") -> dec. | ... AI10: =IF(AI$1=0,"bkt.","dec.") -> dec.
H11: Survey code: quantile (9999 = basket) | L11: ="."&IF(L$1=0,BasketQ,L$1) -> .9999 | M11: ="."&IF(M$1=0,BasketQ,M$1) -> .1 | N11: ="."&IF(N$1=0,BasketQ,N$1) -> .2 | O11: ="."&IF(O$1=0,BasketQ,O$1) -> .3 | P11: ="."&IF(P$1=0,BasketQ,P$1) -> .4 | Q11: ="."&IF(Q$1=0,BasketQ,Q$1) -> .5 | R11: ="."&IF(R$1=0,BasketQ,R$1) -> .6 | S11: ="."&IF(S$1=0,BasketQ,S$1) -> .7 | ... V11: ="."&IF(V$1=0,BasketQ,V$1) -> .10 | Y11: ="."&IF(Y$1=0,BasketQ,Y$1) -> .9999 | Z11: ="."&IF(Z$1=0,BasketQ,Z$1) -> .1 | AA11: ="."&IF(AA$1=0,BasketQ,AA$1) -> .2 | AB11: ="."&IF(AB$1=0,BasketQ,AB$1) -> .3 | AC11: ="."&IF(AC$1=0,BasketQ,AC$1) -> .4 | AD11: ="."&IF(AD$1=0,BasketQ,AD$1) -> .5 | AE11: ="."&IF(AE$1=0,BasketQ,AE$1) -> .6 | AF11: ="."&IF(AF$1=0,BasketQ,AF$1) -> .7 | ... AI11: ="."&IF(AI$1=0,BasketQ,AI$1) -> .10
H12: Analysis year (MTInputs YearDistn) | L12: =L$16 -> 2030 | M12: =L12 -> 2030 | N12: =M12 -> 2030 | O12: =N12 -> 2030 | P12: =O12 -> 2030 | Q12: =P12 -> 2030 | R12: =Q12 -> 2030 | S12: =R12 -> 2030 | T12: =S12 -> 2030 | ... V12: =U12 -> 2030 | Y12: =Y$16 -> 2030 | Z12: =Y12 -> 2030 | AA12: =Z12 -> 2030 | AB12: =AA12 -> 2030 | AC12: =AB12 -> 2030 | AD12: =AC12 -> 2030 | AE12: =AD12 -> 2030 | AF12: =AE12 -> 2030 | AG12: =AF12 -> 2030 | ... AI12: =AH12 -> 2030
A14: 1 | B14: Settings (MTInputs, distributional module assumptions)
A16: YearDistn | D16: =INDEX(MTRowNum,MATCH($A16&"||",MTRowKey,0)) -> 304 | H16: MTInputs: YearDistn | J16: ScenarioDefinition | K16: =LOWER(CtryCode)&".distn."&$A16&IF($B16="","","."&$B16)&IF($C16="","",".dec."&$C16)&"."&K$5 -> egy.distn.YearDistn.1 | L16: =INDEX(ScenarioDefinition!$J$1:$AZ$526,$D16,MATCH(L$5,ScenarioDefinition!$J$5:$AZ$5,0)) -> 2030 | M16: =L16 -> 2030 | N16: =M16 -> 2030 | O16: =N16 -> 2030 | P16: =O16 -> 2030 | Q16: =P16 -> 2030 | R16: =Q16 -> 2030 | S16: =R16 -> 2030 | T16: =S16 -> 2030 | ... V16: =U16 -> 2030 | W16: =IF(X$5=K$5,SUM(Y16:AI16)-SUM(L16:V16),"") | X16: =LOWER(CtryCode)&".distn."&$A16&IF($B16="","","."&$B16)&IF($C16="","",".dec."&$C16)&"."&X$5 -> egy.distn.YearDistn.2 | Y16: =INDEX(ScenarioDefinition!$J$1:$AZ$526,$D16,MATCH(Y$5,ScenarioDefinition!$J$5:$AZ$5,0)) -> 2030 | Z16: =Y16 -> 2030 | AA16: =Z16 -> 2030 | AB16: =AA16 -> 2030 | AC16: =AB16 -> 2030 | AD16: =AC16 -> 2030 | AE16: =AD16 -> 2030 | AF16: =AE16 -> 2030 | AG16: =AF16 -> 2030 | ... AI16: =AH16 -> 2030
A17: QuantilesStatistic | D17: =INDEX(MTRowNum,MATCH($A17&"||",MTRowKey,0)) -> 319 | H17: MTInputs: QuantilesStatistic | J17: ScenarioDefinition | K17: =LOWER(CtryCode)&".distn."&$A17&IF($B17="","","."&$B17)&IF($C17="","",".dec."&$C17)&"."&K$5 -> egy.distn.QuantilesStatistic.1 | L17: =INDEX(ScenarioDefinition!$J$1:$AZ$526,$D17,MATCH(L$5,ScenarioDefinition!$J$5:$AZ$5,0)) -> mean | M17: =L17 -> mean | N17: =M17 -> mean | O17: =N17 -> mean | P17: =O17 -> mean | Q17: =P17 -> mean | R17: =Q17 -> mean | S17: =R17 -> mean | T17: =S17 -> mean | ... V17: =U17 -> mean | W17: =IF(X$5=K$5,SUM(Y17:AI17)-SUM(L17:V17),"") | X17: =LOWER(CtryCode)&".distn."&$A17&IF($B17="","","."&$B17)&IF($C17="","",".dec."&$C17)&"."&X$5 -> egy.distn.QuantilesStatistic.2 | Y17: =INDEX(ScenarioDefinition!$J$1:$AZ$526,$D17,MATCH(Y$5,ScenarioDefinition!$J$5:$AZ$5,0)) -> mean | Z17: =Y17 -> mean | AA17: =Z17 -> mean | AB17: =AA17 -> mean | AC17: =AB17 -> mean | AD17: =AC17 -> mean | AE17: =AD17 -> mean | AF17: =AE17 -> mean | AG17: =AF17 -> mean | ... AI17: =AH17 -> mean
A18: PEDs | D18: =INDEX(MTRowNum,MATCH($A18&"||",MTRowKey,0)) -> 315 | H18: MTInputs: PEDs | J18: ScenarioDefinition | K18: =LOWER(CtryCode)&".distn."&$A18&IF($B18="","","."&$B18)&IF($C18="","",".dec."&$C18)&"."&K$5 -> egy.distn.PEDs.1 | L18: =INDEX(ScenarioDefinition!$J$1:$AZ$526,$D18,MATCH(L$5,ScenarioDefinition!$J$5:$AZ$5,0)) -> Yes | M18: =L18 -> Yes | N18: =M18 -> Yes | O18: =N18 -> Yes | P18: =O18 -> Yes | Q18: =P18 -> Yes | R18: =Q18 -> Yes | S18: =R18 -> Yes | T18: =S18 -> Yes | ... V18: =U18 -> Yes | W18: =IF(X$5=K$5,SUM(Y18:AI18)-SUM(L18:V18),"") | X18: =LOWER(CtryCode)&".distn."&$A18&IF($B18="","","."&$B18)&IF($C18="","",".dec."&$C18)&"."&X$5 -> egy.distn.PEDs.2 | Y18: =INDEX(ScenarioDefinition!$J$1:$AZ$526,$D18,MATCH(Y$5,ScenarioDefinition!$J$5:$AZ$5,0)) -> Yes | Z18: =Y18 -> Yes | AA18: =Z18 -> Yes | AB18: =AA18 -> Yes | AC18: =AB18 -> Yes | AD18: =AC18 -> Yes | AE18: =AD18 -> Yes | AF18: =AE18 -> Yes | AG18: =AF18 -> Yes | ... AI18: =AH18 -> Yes
A19: ScaleGTAP | D19: =INDEX(MTRowNum,MATCH($A19&"||",MTRowKey,0)) -> 316 | H19: MTInputs: ScaleGTAP | J19: ScenarioDefinition | K19: =LOWER(CtryCode)&".distn."&$A19&IF($B19="","","."&$B19)&IF($C19="","",".dec."&$C19)&"."&K$5 -> egy.distn.ScaleGTAP.1 | L19: =INDEX(ScenarioDefinition!$J$1:$AZ$526,$D19,MATCH(L$5,ScenarioDefinition!$J$5:$AZ$5,0)) -> Yes | M19: =L19 -> Yes | N19: =M19 -> Yes | O19: =N19 -> Yes | P19: =O19 -> Yes | Q19: =P19 -> Yes | R19: =Q19 -> Yes | S19: =R19 -> Yes | T19: =S19 -> Yes | ... V19: =U19 -> Yes | W19: =IF(X$5=K$5,SUM(Y19:AI19)-SUM(L19:V19),"") | X19: =LOWER(CtryCode)&".distn."&$A19&IF($B19="","","."&$B19)&IF($C19="","",".dec."&$C19)&"."&X$5 -> egy.distn.ScaleGTAP.2 | Y19: =INDEX(ScenarioDefinition!$J$1:$AZ$526,$D19,MATCH(Y$5,ScenarioDefinition!$J$5:$AZ$5,0)) -> Yes | Z19: =Y19 -> Yes | AA19: =Z19 -> Yes | AB19: =AA19 -> Yes | AC19: =AB19 -> Yes | AD19: =AC19 -> Yes | AE19: =AD19 -> Yes | AF19: =AE19 -> Yes | AG19: =AF19 -> Yes | ... AI19: =AH19 -> Yes
A20: InferredDist | D20: =INDEX(MTRowNum,MATCH($A20&"||",MTRowKey,0)) -> 314 | H20: MTInputs: InferredDist | J20: ScenarioDefinition | K20: =LOWER(CtryCode)&".distn."&$A20&IF($B20="","","."&$B20)&IF($C20="","",".dec."&$C20)&"."&K$5 -> egy.distn.InferredDist.1 | L20: =INDEX(ScenarioDefinition!$J$1:$AZ$526,$D20,MATCH(L$5,ScenarioDefinition!$J$5:$AZ$5,0)) -> No | M20: =L20 -> No | N20: =M20 -> No | O20: =N20 -> No | P20: =O20 -> No | Q20: =P20 -> No | R20: =Q20 -> No | S20: =R20 -> No | T20: =S20 -> No | ... V20: =U20 -> No | W20: =IF(X$5=K$5,SUM(Y20:AI20)-SUM(L20:V20),"") | X20: =LOWER(CtryCode)&".distn."&$A20&IF($B20="","","."&$B20)&IF($C20="","",".dec."&$C20)&"."&X$5 -> egy.distn.InferredDist.2 | Y20: =INDEX(ScenarioDefinition!$J$1:$AZ$526,$D20,MATCH(Y$5,ScenarioDefinition!$J$5:$AZ$5,0)) -> No | Z20: =Y20 -> No | AA20: =Z20 -> No | AB20: =AA20 -> No | AC20: =AB20 -> No | AD20: =AC20 -> No | AE20: =AD20 -> No | AF20: =AE20 -> No | AG20: =AF20 -> No | ... AI20: =AH20 -> No
A21: DWLs | D21: =INDEX(MTRowNum,MATCH($A21&"||",MTRowKey,0)) -> 317 | H21: MTInputs: DWLs | J21: ScenarioDefinition | K21: =LOWER(CtryCode)&".distn."&$A21&IF($B21="","","."&$B21)&IF($C21="","",".dec."&$C21)&"."&K$5 -> egy.distn.DWLs.1 | L21: =INDEX(ScenarioDefinition!$J$1:$AZ$526,$D21,MATCH(L$5,ScenarioDefinition!$J$5:$AZ$5,0)) -> No | M21: =L21 -> No | N21: =M21 -> No | O21: =N21 -> No | P21: =O21 -> No | Q21: =P21 -> No | R21: =Q21 -> No | S21: =R21 -> No | T21: =S21 -> No | ... V21: =U21 -> No | W21: =IF(X$5=K$5,SUM(Y21:AI21)-SUM(L21:V21),"") | X21: =LOWER(CtryCode)&".distn."&$A21&IF($B21="","","."&$B21)&IF($C21="","",".dec."&$C21)&"."&X$5 -> egy.distn.DWLs.2 | Y21: =INDEX(ScenarioDefinition!$J$1:$AZ$526,$D21,MATCH(Y$5,ScenarioDefinition!$J$5:$AZ$5,0)) -> No | Z21: =Y21 -> No | AA21: =Z21 -> No | AB21: =AA21 -> No | AC21: =AB21 -> No | AD21: =AC21 -> No | AE21: =AD21 -> No | AF21: =AE21 -> No | AG21: =AF21 -> No | ... AI21: =AH21 -> No
A22: ExemptMostCook | D22: =INDEX(MTRowNum,MATCH($A22&"||",MTRowKey,0)) -> 312 | H22: MTInputs: ExemptMostCook | J22: ScenarioDefinition | K22: =LOWER(CtryCode)&".distn."&$A22&IF($B22="","","."&$B22)&IF($C22="","",".dec."&$C22)&"."&K$5 -> egy.distn.ExemptMostCook.1 | L22: =INDEX(ScenarioDefinition!$J$1:$AZ$526,$D22,MATCH(L$5,ScenarioDefinition!$J$5:$AZ$5,0)) -> No | M22: =L22 -> No | N22: =M22 -> No | O22: =N22 -> No | P22: =O22 -> No | Q22: =P22 -> No | R22: =Q22 -> No | S22: =R22 -> No | T22: =S22 -> No | ... V22: =U22 -> No | W22: =IF(X$5=K$5,SUM(Y22:AI22)-SUM(L22:V22),"") | X22: =LOWER(CtryCode)&".distn."&$A22&IF($B22="","","."&$B22)&IF($C22="","",".dec."&$C22)&"."&X$5 -> egy.distn.ExemptMostCook.2 | Y22: =INDEX(ScenarioDefinition!$J$1:$AZ$526,$D22,MATCH(Y$5,ScenarioDefinition!$J$5:$AZ$5,0)) -> No | Z22: =Y22 -> No | AA22: =Z22 -> No | AB22: =AA22 -> No | AC22: =AB22 -> No | AD22: =AC22 -> No | AE22: =AD22 -> No | AF22: =AE22 -> No | AG22: =AF22 -> No | ... AI22: =AH22 -> No
A23: ExemptCookDeciles | D23: =INDEX(MTRowNum,MATCH($A23&"||",MTRowKey,0)) -> 313 | H23: MTInputs: ExemptCookDeciles | J23: ScenarioDefinition | K23: =LOWER(CtryCode)&".distn."&$A23&IF($B23="","","."&$B23)&IF($C23="","",".dec."&$C23)&"."&K$5 -> egy.distn.ExemptCookDeciles.1 | L23: =INDEX(ScenarioDefinition!$J$1:$AZ$526,$D23,MATCH(L$5,ScenarioDefinition!$J$5:$AZ$5,0)) -> 4 | M23: =L23 -> 4 | N23: =M23 -> 4 | O23: =N23 -> 4 | P23: =O23 -> 4 | Q23: =P23 -> 4 | R23: =Q23 -> 4 | S23: =R23 -> 4 | T23: =S23 -> 4 | ... V23: =U23 -> 4 | W23: =IF(X$5=K$5,SUM(Y23:AI23)-SUM(L23:V23),"") | X23: =LOWER(CtryCode)&".distn."&$A23&IF($B23="","","."&$B23)&IF($C23="","",".dec."&$C23)&"."&X$5 -> egy.distn.ExemptCookDeciles.2 | Y23: =INDEX(ScenarioDefinition!$J$1:$AZ$526,$D23,MATCH(Y$5,ScenarioDefinition!$J$5:$AZ$5,0)) -> 4 | Z23: =Y23 -> 4 | AA23: =Z23 -> 4 | AB23: =AA23 -> 4 | AC23: =AB23 -> 4 | AD23: =AC23 -> 4 | AE23: =AD23 -> 4 | AF23: =AE23 -> 4 | AG23: =AF23 -> 4 | ... AI23: =AH23 -> 4
A24: EXPLabortax | D24: =INDEX(MTRowNum,MATCH($A24&"||",MTRowKey,0)) -> 197 | H24: MTInputs: EXPLabortax | J24: ScenarioDefinition | K24: =LOWER(CtryCode)&".distn."&$A24&IF($B24="","","."&$B24)&IF($C24="","",".dec."&$C24)&"."&K$5 -> egy.distn.EXPLabortax.1 | L24: =INDEX(ScenarioDefinition!$J$1:$AZ$526,$D24,MATCH(L$5,ScenarioDefinition!$J$5:$AZ$5,0)) -> 30 | M24: =L24 -> 30 | N24: =M24 -> 30 | O24: =N24 -> 30 | P24: =O24 -> 30 | Q24: =P24 -> 30 | R24: =Q24 -> 30 | S24: =R24 -> 30 | T24: =S24 -> 30 | ... V24: =U24 -> 30 | W24: =IF(X$5=K$5,SUM(Y24:AI24)-SUM(L24:V24),"") | X24: =LOWER(CtryCode)&".distn."&$A24&IF($B24="","","."&$B24)&IF($C24="","",".dec."&$C24)&"."&X$5 -> egy.distn.EXPLabortax.2 | Y24: =INDEX(ScenarioDefinition!$J$1:$AZ$526,$D24,MATCH(Y$5,ScenarioDefinition!$J$5:$AZ$5,0)) -> 30 | Z24: =Y24 -> 30 | AA24: =Z24 -> 30 | AB24: =AA24 -> 30 | AC24: =AB24 -> 30 | AD24: =AC24 -> 30 | AE24: =AD24 -> 30 | AF24: =AE24 -> 30 | AG24: =AF24 -> 30 | ... AI24: =AH24 -> 30
A25: EXPCapex | D25: =INDEX(MTRowNum,MATCH($A25&"||",MTRowKey,0)) -> 199 | H25: MTInputs: EXPCapex | J25: ScenarioDefinition | K25: =LOWER(CtryCode)&".distn."&$A25&IF($B25="","","."&$B25)&IF($C25="","",".dec."&$C25)&"."&K$5 -> egy.distn.EXPCapex.1 | L25: =INDEX(ScenarioDefinition!$J$1:$AZ$526,$D25,MATCH(L$5,ScenarioDefinition!$J$5:$AZ$5,0)) -> 50 | M25: =L25 -> 50 | N25: =M25 -> 50 | O25: =N25 -> 50 | P25: =O25 -> 50 | Q25: =P25 -> 50 | R25: =Q25 -> 50 | S25: =R25 -> 50 | T25: =S25 -> 50 | ... V25: =U25 -> 50 | W25: =IF(X$5=K$5,SUM(Y25:AI25)-SUM(L25:V25),"") | X25: =LOWER(CtryCode)&".distn."&$A25&IF($B25="","","."&$B25)&IF($C25="","",".dec."&$C25)&"."&X$5 -> egy.distn.EXPCapex.2 | Y25: =INDEX(ScenarioDefinition!$J$1:$AZ$526,$D25,MATCH(Y$5,ScenarioDefinition!$J$5:$AZ$5,0)) -> 50 | Z25: =Y25 -> 50 | AA25: =Z25 -> 50 | AB25: =AA25 -> 50 | AC25: =AB25 -> 50 | AD25: =AC25 -> 50 | AE25: =AD25 -> 50 | AF25: =AE25 -> 50 | AG25: =AF25 -> 50 | ... AI25: =AH25 -> 50
A26: EXPGoodsandserv | D26: =INDEX(MTRowNum,MATCH($A26&"||",MTRowKey,0)) -> 200 | H26: MTInputs: EXPGoodsandserv | J26: ScenarioDefinition | K26: =LOWER(CtryCode)&".distn."&$A26&IF($B26="","","."&$B26)&IF($C26="","",".dec."&$C26)&"."&K$5 -> egy.distn.EXPGoodsandserv.1 | L26: =INDEX(ScenarioDefinition!$J$1:$AZ$526,$D26,MATCH(L$5,ScenarioDefinition!$J$5:$AZ$5,0)) -> 0 | M26: =L26 -> 0 | N26: =M26 -> 0 | O26: =N26 -> 0 | P26: =O26 -> 0 | Q26: =P26 -> 0 | R26: =Q26 -> 0 | S26: =R26 -> 0 | T26: =S26 -> 0 | ... V26: =U26 -> 0 | W26: =IF(X$5=K$5,SUM(Y26:AI26)-SUM(L26:V26),"") | X26: =LOWER(CtryCode)&".distn."&$A26&IF($B26="","","."&$B26)&IF($C26="","",".dec."&$C26)&"."&X$5 -> egy.distn.EXPGoodsandserv.2 | Y26: =INDEX(ScenarioDefinition!$J$1:$AZ$526,$D26,MATCH(Y$5,ScenarioDefinition!$J$5:$AZ$5,0)) -> 0 | Z26: =Y26 -> 0 | AA26: =Z26 -> 0 | AB26: =AA26 -> 0 | AC26: =AB26 -> 0 | AD26: =AC26 -> 0 | AE26: =AD26 -> 0 | AF26: =AE26 -> 0 | AG26: =AF26 -> 0 | ... AI26: =AH26 -> 0
A27: EXPTransfers | D27: =INDEX(MTRowNum,MATCH($A27&"||",MTRowKey,0)) -> 201 | H27: MTInputs: EXPTransfers | J27: ScenarioDefinition | K27: =LOWER(CtryCode)&".distn."&$A27&IF($B27="","","."&$B27)&IF($C27="","",".dec."&$C27)&"."&K$5 -> egy.distn.EXPTransfers.1 | L27: =INDEX(ScenarioDefinition!$J$1:$AZ$526,$D27,MATCH(L$5,ScenarioDefinition!$J$5:$AZ$5,0)) -> 20 | M27: =L27 -> 20 | N27: =M27 -> 20 | O27: =N27 -> 20 | P27: =O27 -> 20 | Q27: =P27 -> 20 | R27: =Q27 -> 20 | S27: =R27 -> 20 | T27: =S27 -> 20 | ... V27: =U27 -> 20 | W27: =IF(X$5=K$5,SUM(Y27:AI27)-SUM(L27:V27),"") | X27: =LOWER(CtryCode)&".distn."&$A27&IF($B27="","","."&$B27)&IF($C27="","",".dec."&$C27)&"."&X$5 -> egy.distn.EXPTransfers.2 | Y27: =INDEX(ScenarioDefinition!$J$1:$AZ$526,$D27,MATCH(Y$5,ScenarioDefinition!$J$5:$AZ$5,0)) -> 20 | Z27: =Y27 -> 20 | AA27: =Z27 -> 20 | AB27: =AA27 -> 20 | AC27: =AB27 -> 20 | AD27: =AC27 -> 20 | AE27: =AD27 -> 20 | AF27: =AE27 -> 20 | AG27: =AF27 -> 20 | ... AI27: =AH27 -> 20
... A39: QuantilesLCU | D39: =INDEX(MTRowNum,MATCH($A39&"||",MTRowKey,0)) -> 320 | H39: MTInputs: QuantilesLCU | J39: ScenarioDefinition | K39: =LOWER(CtryCode)&".distn."&$A39&IF($B39="","","."&$B39)&IF($C39="","",".dec."&$C39)&"."&K$5 -> egy.distn.QuantilesLCU.1 | L39: =INDEX(ScenarioDefinition!$J$1:$AZ$526,$D39,MATCH(L$5,ScenarioDefinition!$J$5:$AZ$5,0)) -> No | M39: =L39 -> No | N39: =M39 -> No | O39: =N39 -> No | P39: =O39 -> No | Q39: =P39 -> No | R39: =Q39 -> No | S39: =R39 -> No | T39: =S39 -> No | ... V39: =U39 -> No | W39: =IF(X$5=K$5,SUM(Y39:AI39)-SUM(L39:V39),"") | X39: =LOWER(CtryCode)&".distn."&$A39&IF($B39="","","."&$B39)&IF($C39="","",".dec."&$C39)&"."&X$5 -> egy.distn.QuantilesLCU.2 | Y39: =INDEX(ScenarioDefinition!$J$1:$AZ$526,$D39,MATCH(Y$5,ScenarioDefinition!$J$5:$AZ$5,0)) -> No | Z39: =Y39 -> No | AA39: =Z39 -> No | AB39: =AA39 -> No | AC39: =AB39 -> No | AD39: =AC39 -> No | AE39: =AD39 -> No | AF39: =AE39 -> No | AG39: =AF39 -> No | ... AI39: =AH39 -> No
A41: acsvar | H41: Infrastructure access variable of the public investment type | I41: variable | J41: DistMapping (legacy rows 184-189) | K41: =LOWER(CtryCode)&".distn."&$A41&IF($B41="","","."&$B41)&IF($C41="","",".dec."&$C41)&"."&K$5 -> egy.distn.acsvar.1 | L41: =INDEX(DProgCode,MATCH("infra|"&L$36,DProgKey,0)) -> all_acs_share | M41: =L41 -> all_acs_share | N41: =M41 -> all_acs_share | O41: =N41 -> all_acs_share | P41: =O41 -> all_acs_share | Q41: =P41 -> all_acs_share | R41: =Q41 -> all_acs_share | S41: =R41 -> all_acs_share | T41: =S41 -> all_acs_share | ... V41: =U41 -> all_acs_share | W41: =IF(X$5=K$5,SUM(Y41:AI41)-SUM(L41:V41),"") | X41: =LOWER(CtryCode)&".distn."&$A41&IF($B41="","","."&$B41)&IF($C41="","",".dec."&$C41)&"."&X$5 -> egy.distn.acsvar.2 | Y41: =INDEX(DProgCode,MATCH("infra|"&Y$36,DProgKey,0)) -> all_acs_share | Z41: =Y41 -> all_acs_share | AA41: =Z41 -> all_acs_share | AB41: =AA41 -> all_acs_share | AC41: =AB41 -> all_acs_share | AD41: =AC41 -> all_acs_share | AE41: =AD41 -> all_acs_share | AF41: =AE41 -> all_acs_share | AG41: =AF41 -> all_acs_share | ... AI41: =AH41 -> all_acs_share
A42: aspcode | H42: ASPIRE program of the current spending type | I42: program | J42: DistMapping (legacy rows 195-210) | K42: =LOWER(CtryCode)&".distn."&$A42&IF($B42="","","."&$B42)&IF($C42="","",".dec."&$C42)&"."&K$5 -> egy.distn.aspcode.1 | L42: =INDEX(DProgCode,MATCH("aspire|"&L$37,DProgKey,0)) -> per_allsp.avt_q | M42: =L42 -> per_allsp.avt_q | N42: =M42 -> per_allsp.avt_q | O42: =N42 -> per_allsp.avt_q | P42: =O42 -> per_allsp.avt_q | Q42: =P42 -> per_allsp.avt_q | R42: =Q42 -> per_allsp.avt_q | S42: =R42 -> per_allsp.avt_q | T42: =S42 -> per_allsp.avt_q | ... V42: =U42 -> per_allsp.avt_q | W42: =IF(X$5=K$5,SUM(Y42:AI42)-SUM(L42:V42),"") | X42: =LOWER(CtryCode)&".distn."&$A42&IF($B42="","","."&$B42)&IF($C42="","",".dec."&$C42)&"."&X$5 -> egy.distn.aspcode.2 | Y42: =INDEX(DProgCode,MATCH("aspire|"&Y$37,DProgKey,0)) -> per_allsp.avt_q | Z42: =Y42 -> per_allsp.avt_q | AA42: =Z42 -> per_allsp.avt_q | AB42: =AA42 -> per_allsp.avt_q | AC42: =AB42 -> per_allsp.avt_q | AD42: =AC42 -> per_allsp.avt_q | AE42: =AD42 -> per_allsp.avt_q | AF42: =AE42 -> per_allsp.avt_q | AG42: =AF42 -> per_allsp.avt_q | ... AI42: =AH42 -> per_allsp.avt_q
A43: exfuel | H43: Most-used cooking fuel (WHOCooking, overall) | I43: item | J43: WHOCooking (legacy row 226) | K43: =LOWER(CtryCode)&".distn."&$A43&IF($B43="","","."&$B43)&IF($C43="","",".dec."&$C43)&"."&K$5 -> egy.distn.exfuel.1 | L43: =INDEX(DCookFuel,MATCH(CtryCode&".distn.pcoff.ove",DCookKey,0)) -> lpg | M43: =L43 -> lpg | N43: =M43 -> lpg | O43: =N43 -> lpg | P43: =O43 -> lpg | Q43: =P43 -> lpg | R43: =Q43 -> lpg | S43: =R43 -> lpg | T43: =S43 -> lpg | ... V43: =U43 -> lpg | W43: =IF(X$5=K$5,SUM(Y43:AI43)-SUM(L43:V43),"") | X43: =LOWER(CtryCode)&".distn."&$A43&IF($B43="","","."&$B43)&IF($C43="","",".dec."&$C43)&"."&X$5 -> egy.distn.exfuel.2 | Y43: =INDEX(DCookFuel,MATCH(CtryCode&".distn.pcoff.ove",DCookKey,0)) -> lpg | Z43: =Y43 -> lpg | AA43: =Z43 -> lpg | AB43: =AA43 -> lpg | AC43: =AB43 -> lpg | AD43: =AC43 -> lpg | AE43: =AD43 -> lpg | AF43: =AE43 -> lpg | AG43: =AF43 -> lpg | ... AI43: =AH43 -> lpg
A44: exdec | H44: Exempt decile of the most-used cooking fuel (1 = exempt) | I44: flag | J44: MTInputs ExemptMostCook, ExemptCookDeciles (legacy row 1579) | K44: =LOWER(CtryCode)&".distn."&$A44&IF($B44="","","."&$B44)&IF($C44="","",".dec."&$C44)&"."&K$5 -> egy.distn.exdec.1 | L44: =IF(AND(LEFT(L$22,3)="Yes",L$1>0,L$1<=L$23),1,0) -> 0 | M44: =IF(AND(LEFT(M$22,3)="Yes",M$1>0,M$1<=M$23),1,0) -> 0 | N44: =IF(AND(LEFT(N$22,3)="Yes",N$1>0,N$1<=N$23),1,0) -> 0 | O44: =IF(AND(LEFT(O$22,3)="Yes",O$1>0,O$1<=O$23),1,0) -> 0 | P44: =IF(AND(LEFT(P$22,3)="Yes",P$1>0,P$1<=P$23),1,0) -> 0 | Q44: =IF(AND(LEFT(Q$22,3)="Yes",Q$1>0,Q$1<=Q$23),1,0) -> 0 | R44: =IF(AND(LEFT(R$22,3)="Yes",R$1>0,R$1<=R$23),1,0) -> 0 | S44: =IF(AND(LEFT(S$22,3)="Yes",S$1>0,S$1<=S$23),1,0) -> 0 | ... V44: =IF(AND(LEFT(V$22,3)="Yes",V$1>0,V$1<=V$23),1,0) -> 0 | W44: =IF(X$5=K$5,SUM(Y44:AI44)-SUM(L44:V44),"") | X44: =LOWER(CtryCode)&".distn."&$A44&IF($B44="","","."&$B44)&IF($C44="","",".dec."&$C44)&"."&X$5 -> egy.distn.exdec.2 | Y44: =IF(AND(LEFT(Y$22,3)="Yes",Y$1>0,Y$1<=Y$23),1,0) -> 0 | Z44: =IF(AND(LEFT(Z$22,3)="Yes",Z$1>0,Z$1<=Z$23),1,0) -> 0 | AA44: =IF(AND(LEFT(AA$22,3)="Yes",AA$1>0,AA$1<=AA$23),1,0) -> 0 | AB44: =IF(AND(LEFT(AB$22,3)="Yes",AB$1>0,AB$1<=AB$23),1,0) -> 0 | AC44: =IF(AND(LEFT(AC$22,3)="Yes",AC$1>0,AC$1<=AC$23),1,0) -> 0 | AD44: =IF(AND(LEFT(AD$22,3)="Yes",AD$1>0,AD$1<=AD$23),1,0) -> 0 | AE44: =IF(AND(LEFT(AE$22,3)="Yes",AE$1>0,AE$1<=AE$23),1,0) -> 0 | AF44: =IF(AND(LEFT(AF$22,3)="Yes",AF$1>0,AF$1<=AF$23),1,0) -> 0 | ... AI44: =IF(AND(LEFT(AI$22,3)="Yes",AI$1>0,AI$1<=AI$23),1,0) -> 0
A45: tgtcode | H45: ASPIRE program of the transfer type (Cash: cash transfer) | I45: program | J45: DistMapping (legacy I216; v0.6.0) | K45: =LOWER(CtryCode)&".distn."&$A45&IF($B45="","","."&$B45)&IF($C45="","",".dec."&$C45)&"."&K$5 -> egy.distn.tgtcode.1 | L45: =IFERROR(INDEX(DProgCode,MATCH("aspire|"&L$31,DProgKey,0)),"Cash") -> Cash | M45: =L45 -> Cash | N45: =M45 -> Cash | O45: =N45 -> Cash | P45: =O45 -> Cash | Q45: =P45 -> Cash | R45: =Q45 -> Cash | S45: =R45 -> Cash | T45: =S45 -> Cash | ... V45: =U45 -> Cash | W45: =IF(X$5=K$5,SUM(Y45:AI45)-SUM(L45:V45),"") | X45: =LOWER(CtryCode)&".distn."&$A45&IF($B45="","","."&$B45)&IF($C45="","",".dec."&$C45)&"."&X$5 -> egy.distn.tgtcode.2 | Y45: =IFERROR(INDEX(DProgCode,MATCH("aspire|"&Y$31,DProgKey,0)),"Cash") -> Cash | Z45: =Y45 -> Cash | AA45: =Z45 -> Cash | AB45: =AA45 -> Cash | AC45: =AB45 -> Cash | AD45: =AC45 -> Cash | AE45: =AD45 -> Cash | AF45: =AE45 -> Cash | AG45: =AF45 -> Cash | ... AI45: =AH45 -> Cash
A46: tgtdata | H46: ASPIRE data for the transfer program and the country (1 = yes) | I46: flag | J46: ASPIRE (legacy I213; v0.6.0) | K46: =LOWER(CtryCode)&".distn."&$A46&IF($B46="","","."&$B46)&IF($C46="","",".dec."&$C46)&"."&K$5 -> egy.distn.tgtdata.1 | L46: =IF(ISNUMBER(MATCH(CtryCode&"."&L$45&"1_preT_tot",DAspKey,0)),1,0) -> 0 | M46: =L46 -> 0 | N46: =M46 -> 0 | O46: =N46 -> 0 | P46: =O46 -> 0 | Q46: =P46 -> 0 | R46: =Q46 -> 0 | S46: =R46 -> 0 | T46: =S46 -> 0 | ... V46: =U46 -> 0 | W46: =IF(X$5=K$5,SUM(Y46:AI46)-SUM(L46:V46),"") | X46: =LOWER(CtryCode)&".distn."&$A46&IF($B46="","","."&$B46)&IF($C46="","",".dec."&$C46)&"."&X$5 -> egy.distn.tgtdata.2 | Y46: =IF(ISNUMBER(MATCH(CtryCode&"."&Y$45&"1_preT_tot",DAspKey,0)),1,0) -> 0 | Z46: =Y46 -> 0 | AA46: =Z46 -> 0 | AB46: =AA46 -> 0 | AC46: =AB46 -> 0 | AD46: =AC46 -> 0 | AE46: =AD46 -> 0 | AF46: =AE46 -> 0 | AG46: =AF46 -> 0 | ... AI46: =AH46 -> 0
A47: plvar | H47: Survey variable of the poverty line (TargetBelow; popw if none) | I47: variable | J47: HHSurvey pct_belowpl_* (legacy Q2551; v0.6.0) | K47: =LOWER(CtryCode)&".distn."&$A47&IF($B47="","","."&$B47)&IF($C47="","",".dec."&$C47)&"."&K$5 -> egy.distn.plvar.1 | L47: =IF(LEFT(L$32&"",2)="No","popw","pct_belowpl_"&SUBSTITUTE(L$32&"",".","")) -> popw | M47: =L47 -> popw | N47: =M47 -> popw | O47: =N47 -> popw | P47: =O47 -> popw | Q47: =P47 -> popw | R47: =Q47 -> popw | S47: =R47 -> popw | T47: =S47 -> popw | ... V47: =U47 -> popw | W47: =IF(X$5=K$5,SUM(Y47:AI47)-SUM(L47:V47),"") | X47: =LOWER(CtryCode)&".distn."&$A47&IF($B47="","","."&$B47)&IF($C47="","",".dec."&$C47)&"."&X$5 -> egy.distn.plvar.2 | Y47: =IF(LEFT(Y$32&"",2)="No","popw","pct_belowpl_"&SUBSTITUTE(Y$32&"",".","")) -> popw | Z47: =Y47 -> popw | AA47: =Z47 -> popw | AB47: =AA47 -> popw | AC47: =AB47 -> popw | AD47: =AC47 -> popw | AE47: =AD47 -> popw | AF47: =AE47 -> popw | AG47: =AF47 -> popw | ... AI47: =AH47 -> popw
